Workbook

Sheet Test cases
A1: Mã TC | B1: Module | C1: Use case | D1: Tiêu đề | E1: Tiền điều kiện | F1: Các bước thực hiện | G1: Dữ liệu kiểm thử | H1: Kết quả mong đợi | I1: Mức độ | J1: Trạng thái | K1: Ghi chú
A2: TC-001 | B2: Tài khoản | C2: UC-03 | D2: Đăng ký thành công | E2: Chưa có tài khoản | F2: 1. Mở Đăng ký 2. Nhập thông tin hợp lệ 3. Nhập OTP đúng | G2: Email mới, SĐT mới, năm sinh 2005 | H2: Tạo tài khoản VIEWER, số dư 0 xu, đăng nhập tự động | I2: Cao | J2: Đạt | K2: Đạt ở mức API: tạo tài khoản VIEWER, ACTIVE, số dư 0 xu. Lưu ý: ứng dụng chưa có bước OTP nên bước 3 của TC không thực hiện được (xem BUG-21); “đăng nhập tự động” thuộc giao diện nên chưa kiểm tra. Test: tests/01-auth.test.mjs (tìm “TC-001”)
A3: TC-002 | B3: Tài khoản | C3: UC-03 | D3: Đăng ký trùng email | E3: Email đã tồn tại | F3: Đăng ký với email đã dùng | G3: Email trùng | H3: Báo “Thông tin này đã được dùng cho một tài khoản khác” | I3: Cao | J3: Đạt | K3: Đạt: đăng ký trùng email bị từ chối, không tạo thêm tài khoản. Chữ trong thông báo khác câu mẫu của TC nhưng cùng ý. HTTP 400 (API-01 ghi 409, xem BUG-33). Test: tests/01-auth.test.mjs (tìm “TC-002”)
A4: TC-003 | B4: Tài khoản | C4: UC-03 | D4: Đăng ký trùng số điện thoại | E4: SĐT đã tồn tại | F4: Đăng ký với SĐT đã dùng | G4: SĐT trùng | H4: Báo trùng, không tạo tài khoản | I4: Cao | J4: Đạt | K4: Đạt: đăng ký trùng số điện thoại bị từ chối, không tạo tài khoản. HTTP 400 (API-01 ghi 409, xem BUG-33). Test: tests/01-auth.test.mjs (tìm “TC-003”)
A5: TC-004 | B5: Tài khoản | C5: UC-03 | D5: Dưới 16 tuổi | E5: — | F5: Đăng ký với năm sinh khiến dưới 16 tuổi | G5: Năm sinh 2015 | H5: Từ chối đăng ký | I5: Trung bình | J5: Đạt | K5: Đạt: năm sinh 2015 bị từ chối, không tạo tài khoản; biên 15/16 tuổi cũng đúng (EXT-02). Lưu ý: bỏ trống năm sinh thì qua mặt được kiểm tra này (BUG-28). Test: tests/01-auth.test.mjs (tìm “TC-004”)
A6: TC-005 | B6: Tài khoản | C6: UC-03 | D6: OTP sai 3 lần | E6: Đang ở bước OTP | F6: Nhập sai OTP 3 lần | G6: OTP 000000 | H6: Yêu cầu gửi OTP mới | I6: Trung bình | J6: Không đạt | K6: Chưa cài đặt: không có endpoint xác thực OTP (/auth/verify-otp); đăng ký tạo tài khoản ngay không qua OTP nên không có cơ chế “sai 3 lần thì gửi OTP mới”. Lỗi: BUG-21 Test: tests/01-auth.test.mjs (tìm “TC-005”)
A7: TC-006 | B7: Tài khoản | C7: UC-03 | D7: OTP hết hạn | E7: Đã gửi OTP | F7: Chờ quá 5 phút rồi nhập OTP đúng | G7: — | H7: Báo OTP hết hạn | I7: Trung bình | J7: Không đạt | K7: Chưa cài đặt: không có OTP nên không có OTP để hết hạn sau 5 phút. Lỗi: BUG-21 Test: tests/01-auth.test.mjs (tìm “TC-006”)
A8: TC-007 | B8: Tài khoản | C8: UC-G04 | D8: Đăng nhập tài khoản bị khóa | E8: Tài khoản LOCKED | F8: Đăng nhập | G8: — | H8: Từ chối, hiển thị tài khoản bị khóa | I8: Cao | J8: Không đạt | K8: Đăng nhập tài khoản LOCKED trả HTTP 200, success = true và trả cả dữ liệu người dùng; chỉ đổi câu thông báo (API-01 yêu cầu 403). Lỗi: BUG-07 Test: tests/01-auth.test.mjs (tìm “TC-007”)
A9: TC-008 | B9: Xem QC | C9: UC-V01 | D9: Chỉ hiện quảng cáo ACTIVE còn ngân sách | E9: Có quảng cáo ACTIVE, PAUSED, ENDED | F9: Mở danh sách quảng cáo | G9: — | H9: Chỉ hiện quảng cáo ACTIVE còn ngân sách | I9: Cao | J9: Đạt | K9: Đạt: danh sách chỉ gồm QC ACTIVE, còn ngân sách và trong khoảng ngày chạy; QC PENDING/PAUSED/ENDED/REJECTED, hết ngân sách, hết hạn hoặc chưa tới ngày đều không hiện. Test: tests/02-ads-list.test.mjs (tìm “TC-008”)
A10: TC-009 | B10: Xem QC | C10: UC-V01 | D10: Lọc theo đối tượng mục tiêu | E10: QC chỉ cho nữ 18–24 Hà Nội | F10: Đăng nhập bằng nam 30 tuổi và xem danh sách | G10: Viewer nam | H10: Không thấy quảng cáo đó | I10: Cao | J10: Không đạt | K10: Nam 30 tuổi vẫn thấy QC nhắm nữ 18–24 tuổi Hà Nội (người đúng đối tượng thì vẫn thấy đúng). GET /api/ads không dùng bảng ad_targeting. Lỗi: BUG-10 Test: tests/02-ads-list.test.mjs (tìm “TC-009”) – 2 test: 1 đạt, 1 không đạt
A11: TC-010 | B11: Xem QC | C11: UC-V01 | D11: Lọc theo danh mục | E11: Có QC nhiều danh mục | F11: Chọn chip “Giáo dục” | G11: — | H11: Chỉ hiện quảng cáo danh mục Giáo dục | I11: Trung bình | J11: Đạt | K11: Đạt: lọc theo category chỉ trả quảng cáo của danh mục được chọn. Test: tests/02-ads-list.test.mjs (tìm “TC-010”)
A12: TC-011 | B12: Xem QC | C12: UC-V01 | D12: Quảng cáo đã xem hôm nay | E12: Đã xem QC #101 hôm nay | F12: Mở danh sách | G12: — | H12: QC #101 hiện “Đã xem hôm nay”, nút bị khóa | I12: Cao | J12: Đạt | K12: Đạt ở mức API: QC đã hoàn tất hôm nay có viewed_today > 0; lượt STARTED/INVALID không làm QC bị khóa. Chữ “Đã xem hôm nay” và việc khóa nút thuộc giao diện nên chưa kiểm tra trên trình duyệt. Test: tests/02-ads-list.test.mjs (tìm “TC-011”) – 2 test: 2 đạt, 0 không đạt
... A46: TC-045 | B46: Báo cáo | C46: UC-AD06 | D46: Xuất báo cáo Excel | E46: Có dữ liệu giao dịch | F46: Admin xuất báo cáo | G46: — | H46: File có xu phát hành, xu đã đổi, chi phí QC khớp dữ liệu | I46: Trung bình | J46: Không đạt | K46: Chưa cài đặt: không có chức năng xuất báo cáo Excel (UC-AD06). /api/admin/stats chỉ trả số liệu JSON và số liệu đó khớp dữ liệu. Lỗi: BUG-24 Test: tests/05-ads-admin.test.mjs (tìm “TC-045”)

Sheet Tổng hợp
A1: TỔNG HỢP KẾT QUẢ KIỂM THỬ
A2: Đề tài: YouTube Xu – Xem quảng cáo nhận xu · Kế hoạch: TEST-01 · Test case: TC-01
A4: 1. Thông tin lần chạy (TEST-01 §Báo cáo kết quả)
A5: Phiên bản build | B5: youtube-xu-web 1.0.0 (package.json) – gói nộp Sprint_Youtube_Xu_da_chinh_sua.rar, SHA-256 114c3d54d1c37081…
A6: Người chạy | B6: Claude (trợ lý AI) chạy tự động bằng bộ test trong thư mục tests/ theo yêu cầu của nhóm
A7: Thời gian chạy | B7: 28/10/2026 21:27 (giờ Việt Nam)
A8: Môi trường | B8: Node.js v22.23.4 trên Linux. CSDL giả lập SQLite trong bộ nhớ, dựng theo schema của nhóm – KHÔNG phải MySQL 8 thật trên XAMPP
A9: Phạm vi đã kiểm | B9: Mức API/CSDL: gọi trực tiếp các route handler thật trong app/api với các câu SQL thật. Chưa kiểm: giao diện trình duyệt, hiệu năng 500 người xem (k6/JMeter), responsive di động
A10: Chạy lại | B10: Trong thư mục dự án: node tests/run.mjs (cần Node ≥ 22.5; xem tests/README.md). Chạy riêng một TC: node tests/run.mjs --test-name-pattern="TC-013"
A12: 2. Kết quả theo test case (sheet “Test cases”)
A13: Chỉ tiêu | B13: Số lượng | C13: Tỷ lệ
A14: Tổng số test case | B14: =COUNTA('Test cases'!$A$2:$A$200) -> 45
A15: Đạt | B15: =COUNTIF('Test cases'!$J$2:$J$200,"Đạt") -> 20 | C15: =IF($B$14=0,0,B15/$B$14) -> 0.44444444
A16: Không đạt | B16: =COUNTIF('Test cases'!$J$2:$J$200,"Không đạt") -> 25 | C16: =IF($B$14=0,0,B16/$B$14) -> 0.55555556
A17: Chặn | B17: =COUNTIF('Test cases'!$J$2:$J$200,"Chặn") -> 0 | C17: =IF($B$14=0,0,B17/$B$14) -> 0
A18: Chưa chạy | B18: =COUNTIF('Test cases'!$J$2:$J$200,"Chưa chạy") -> 0 | C18: =IF($B$14=0,0,B18/$B$14) -> 0
A20: 3. Tiêu chí ra (TEST-01 §4)
A21: Tiêu chí | B21: Hiện tại | C21: Yêu cầu | D21: Kết luận | E21: Chi tiết
A22: 100% test case mức Cao đã chạy và đạt | B22: =IF(COUNTIF('Test cases'!$I$2:$I$200,"Cao")=0,0,COUNTIFS('Test cases'!$I$2:$I$200,"Cao",'Test cases'!$J$2:$J$200,"Đạt")/COUNTIF('Test cases'!$I$2:$I$200,"Cao")) -> 0.47058824 | C22: 1 | D22: =IF(B22>=C22,"ĐẠT","CHƯA ĐẠT") -> CHƯA ĐẠT | E22: =COUNTIFS('Test cases'!$I$2:$I$200,"Cao",'Test cases'!$J$2:$J$200,"Đạt")&"/"&COUNTIF('Test cases'!$I$2:$I$200,"Cao")&" TC mức Cao đạt" -> 16/34 TC mức Cao đạt
A23: Không còn lỗi nghiêm trọng (sai số dư xu, lộ quyền) | B23: =COUNTIFS('Danh sách lỗi'!$B$2:$B$200,"Nghiêm trọng",'Danh sách lỗi'!$I$2:$I$200,"<>Đã đóng") -> 6 | C23: 0 | D23: =IF(B23<=C23,"ĐẠT","CHƯA ĐẠT") -> CHƯA ĐẠT | E23: ="lỗi nghiêm trọng đang mở" -> lỗi nghiêm trọng đang mở
A24: ≥ 90% test case tổng thể đạt | B24: =IF($B$14=0,0,$B$15/$B$14) -> 0.44444444 | C24: 0.9 | D24: =IF(B24>=C24,"ĐẠT","CHƯA ĐẠT") -> CHƯA ĐẠT | E24: =$B$15&"/"&$B$14&" test case đạt" -> 20/45 test case đạt
A26: 4. Kết quả theo module
A27: Module | B27: Tổng | C27: Đạt | D27: Không đạt | E27: Chặn | F27: Chưa chạy | G27: Tỷ lệ đạt
A28: Tài khoản | B28: =COUNTIF('Test cases'!$B$2:$B$200,$A28) -> 7 | C28: =COUNTIFS('Test cases'!$B$2:$B$200,$A28,'Test cases'!$J$2:$J$200,"Đạt") -> 4 | D28: =COUNTIFS('Test cases'!$B$2:$B$200,$A28,'Test cases'!$J$2:$J$200,"Không đạt") -> 3 | E28: =COUNTIFS('Test cases'!$B$2:$B$200,$A28,'Test cases'!$J$2:$J$200,"Chặn") -> 0 | F28: =COUNTIFS('Test cases'!$B$2:$B$200,$A28,'Test cases'!$J$2:$J$200,"Chưa chạy") -> 0 | G28: =IF(B28=0,0,C28/B28) -> 0.57142857
A29: Xem QC | B29: =COUNTIF('Test cases'!$B$2:$B$200,$A29) -> 17 | C29: =COUNTIFS('Test cases'!$B$2:$B$200,$A29,'Test cases'!$J$2:$J$200,"Đạt") -> 6 | D29: =COUNTIFS('Test cases'!$B$2:$B$200,$A29,'Test cases'!$J$2:$J$200,"Không đạt") -> 11 | E29: =COUNTIFS('Test cases'!$B$2:$B$200,$A29,'Test cases'!$J$2:$J$200,"Chặn") -> 0 | F29: =COUNTIFS('Test cases'!$B$2:$B$200,$A29,'Test cases'!$J$2:$J$200,"Chưa chạy") -> 0 | G29: =IF(B29=0,0,C29/B29) -> 0.35294118
A30: Ví xu | B30: =COUNTIF('Test cases'!$B$2:$B$200,$A30) -> 2 | C30: =COUNTIFS('Test cases'!$B$2:$B$200,$A30,'Test cases'!$J$2:$J$200,"Đạt") -> 2 | D30: =COUNTIFS('Test cases'!$B$2:$B$200,$A30,'Test cases'!$J$2:$J$200,"Không đạt") -> 0 | E30: =COUNTIFS('Test cases'!$B$2:$B$200,$A30,'Test cases'!$J$2:$J$200,"Chặn") -> 0 | F30: =COUNTIFS('Test cases'!$B$2:$B$200,$A30,'Test cases'!$J$2:$J$200,"Chưa chạy") -> 0 | G30: =IF(B30=0,0,C30/B30) -> 1
A31: Đổi quà | B31: =COUNTIF('Test cases'!$B$2:$B$200,$A31) -> 7 | C31: =COUNTIFS('Test cases'!$B$2:$B$200,$A31,'Test cases'!$J$2:$J$200,"Đạt") -> 4 | D31: =COUNTIFS('Test cases'!$B$2:$B$200,$A31,'Test cases'!$J$2:$J$200,"Không đạt") -> 3 | E31: =COUNTIFS('Test cases'!$B$2:$B$200,$A31,'Test cases'!$J$2:$J$200,"Chặn") -> 0 | F31: =COUNTIFS('Test cases'!$B$2:$B$200,$A31,'Test cases'!$J$2:$J$200,"Chưa chạy") -> 0 | G31: =IF(B31=0,0,C31/B31) -> 0.57142857
A32: Quảng cáo | B32: =COUNTIF('Test cases'!$B$2:$B$200,$A32) -> 5 | C32: =COUNTIFS('Test cases'!$B$2:$B$200,$A32,'Test cases'!$J$2:$J$200,"Đạt") -> 4 | D32: =COUNTIFS('Test cases'!$B$2:$B$200,$A32,'Test cases'!$J$2:$J$200,"Không đạt") -> 1 | E32: =COUNTIFS('Test cases'!$B$2:$B$200,$A32,'Test cases'!$J$2:$J$200,"Chặn") -> 0 | F32: =COUNTIFS('Test cases'!$B$2:$B$200,$A32,'Test cases'!$J$2:$J$200,"Chưa chạy") -> 0 | G32: =IF(B32=0,0,C32/B32) -> 0.8
A33: Phân quyền | B33: =COUNTIF('Test cases'!$B$2:$B$200,$A33) -> 2 | C33: =COUNTIFS('Test cases'!$B$2:$B$200,$A33,'Test cases'!$J$2:$J$200,"Đạt") -> 0 | D33: =COUNTIFS('Test cases'!$B$2:$B$200,$A33,'Test cases'!$J$2:$J$200,"Không đạt") -> 2 | E33: =COUNTIFS('Test cases'!$B$2:$B$200,$A33,'Test cases'!$J$2:$J$200,"Chặn") -> 0 | F33: =COUNTIFS('Test cases'!$B$2:$B$200,$A33,'Test cases'!$J$2:$J$200,"Chưa chạy") -> 0 | G33: =IF(B33=0,0,C33/B33) -> 0
A34: Gian lận | B34: =COUNTIF('Test cases'!$B$2:$B$200,$A34) -> 4 | C34: =COUNTIFS('Test cases'!$B$2:$B$200,$A34,'Test cases'!$J$2:$J$200,"Đạt") -> 0 | D34: =COUNTIFS('Test cases'!$B$2:$B$200,$A34,'Test cases'!$J$2:$J$200,"Không đạt") -> 4 | E34: =COUNTIFS('Test cases'!$B$2:$B$200,$A34,'Test cases'!$J$2:$J$200,"Chặn") -> 0 | F34: =COUNTIFS('Test cases'!$B$2:$B$200,$A34,'Test cases'!$J$2:$J$200,"Chưa chạy") -> 0 | G34: =IF(B34=0,0,C34/B34) -> 0
A35: Báo cáo | B35: =COUNTIF('Test cases'!$B$2:$B$200,$A35) -> 1 | C35: =COUNTIFS('Test cases'!$B$2:$B$200,$A35,'Test cases'!$J$2:$J$200,"Đạt") -> 0 | D35: =COUNTIFS('Test cases'!$B$2:$B$200,$A35,'Test cases'!$J$2:$J$200,"Không đạt") -> 1 | E35: =COUNTIFS('Test cases'!$B$2:$B$200,$A35,'Test cases'!$J$2:$J$200,"Chặn") -> 0 | F35: =COUNTIFS('Test cases'!$B$2:$B$200,$A35,'Test cases'!$J$2:$J$200,"Chưa chạy") -> 0 | G35: =IF(B35=0,0,C35/B35) -> 0
A36: Cộng | B36: =SUM(B28:B35) -> 45 | C36: =SUM(C28:C35) -> 20 | D36: =SUM(D28:D35) -> 25 | E36: =SUM(E28:E35) -> 0 | F36: =SUM(F28:F35) -> 0 | G36: =IF(B36=0,0,C36/B36) -> 0.44444444
A38: 5. Lỗi theo mức độ (sheet “Danh sách lỗi”)
A39: Mức độ (TEST-01 §5) | B39: Số lỗi | C39: Đang mở
A40: Nghiêm trọng | B40: =COUNTIF('Danh sách lỗi'!$B$2:$B$200,$A40) -> 6 | C40: =COUNTIFS('Danh sách lỗi'!$B$2:$B$200,$A40,'Danh sách lỗi'!$I$2:$I$200,"<>Đã đóng") -> 6
A41: Cao | B41: =COUNTIF('Danh sách lỗi'!$B$2:$B$200,$A41) -> 14 | C41: =COUNTIFS('Danh sách lỗi'!$B$2:$B$200,$A41,'Danh sách lỗi'!$I$2:$I$200,"<>Đã đóng") -> 14
A42: Trung bình | B42: =COUNTIF('Danh sách lỗi'!$B$2:$B$200,$A42) -> 12 | C42: =COUNTIFS('Danh sách lỗi'!$B$2:$B$200,$A42,'Danh sách lỗi'!$I$2:$I$200,"<>Đã đóng") -> 12
A43: Thấp | B43: =COUNTIF('Danh sách lỗi'!$B$2:$B$200,$A43) -> 2 | C43: =COUNTIFS('Danh sách lỗi'!$B$2:$B$200,$A43,'Danh sách lỗi'!$I$2:$I$200,"<>Đã đóng") -> 2
A44: Cộng | B44: =SUM(B40:B43) -> 34 | C44: =SUM(C40:C43) -> 34
A46: 6. Test tự động (sheet “Chi tiết lần chạy”)
...

Sheet Danh sách lỗi
A1: Mã lỗi | B1: Mức độ | C1: Tiêu đề | D1: Mô tả (thực tế) | E1: Test case (TC-01) | F1: Test tự động (bằng chứng) | G1: Vị trí trong mã nguồn | H1: Gợi ý sửa | I1: Trạng thái
A2: BUG-01 | B2: Nghiêm trọng | C2: Không có xác thực: API không kiểm tra JWT, tin userId/role do client gửi | D2: Đăng nhập không phát hành token (AUTH_SECRET trong .env.local không được dùng ở đâu). 15 API được thử (redeem, views/start, views/complete, wallet, auth/me, affiliate, redemptions, ads?role=ADMIN, tạo QC, đổi trạng thái QC, xử lý đơn, tạo quà, admin/stats, admin/fraud GET và POST) đều vẫn xử lý khi không có token hoặc token giả (HTTP 200/400) thay vì trả 401. | E2: TC-039 | F2: tests/01-auth.test.mjs: SEC-06 tests/06-security.test.mjs: SEC-13…SEC-27 | G2: Toàn bộ app/api/**/route.js; auth/login/route.js L58–62 (không phát hành token); .env.local (AUTH_SECRET chưa dùng) | H2: Đăng nhập ký JWT bằng AUTH_SECRET (jose hoặc jsonwebtoken, hạn 1–24 giờ) và trả cho client. Viết hàm dùng chung requireAuth(request, {roles}) đọc Authorization: Bearer, trả 401 nếu thiếu/sai/hết hạn. Mọi route lấy user_id từ token, không đọc từ body, query hay header x-user-id. | I2: Mới
A3: BUG-02 | B3: Nghiêm trọng | C3: Không phân quyền theo vai trò: Viewer/Nhà QC gọi được chức năng Admin | D3: “Vai trò” chỉ là tham số ?role=ADMIN trên URL. Viewer #5 gọi GET /api/ads?role=ADMIN nhận HTTP 200 kèm dữ liệu (TC-039 yêu cầu 403). Viewer tạo được quà thẻ 500.000đ giá 1 xu rồi tự đổi (SEC-32); Nhà QC tự chuyển QC của mình từ PENDING sang ACTIVE, bỏ qua bước Admin duyệt (SEC-33); Viewer khóa tài khoản và thu hồi xu của người khác (SEC-34); Viewer tự duyệt đơn đổi quà lớn của chính mình và nhận mã thẻ (SEC-35). | E3: TC-039 | F3: tests/05-ads-admin.test.mjs: TC-039 tests/06-security.test.mjs: SEC-32…SEC-35 | G3: ads/route.js L9, L14 (role từ query); rewards/route.js L19–35; ads/[id]/status/route.js L4–22; admin/fraud/route.js L6, L42–112; admin/stats/route.js L6; redemptions/[id]/process/route.js L5–10 | H3: Sau khi có JWT (BUG-01), kiểm tra role lấy từ token: /admin/*, POST /rewards, PATCH /ads/[id]/status và PATCH /redemptions/[id]/process chỉ cho ADMIN (trả 403); POST /ads chỉ cho ADVERTISER. admin_id/reviewed_by lấy từ token, không nhận từ body. | I3: Mới
A4: BUG-03 | B4: Nghiêm trọng | C4: Truy cập chéo dữ liệu người khác (IDOR): ví, hồ sơ, mã thẻ, đổi quà, chiến dịch | D4: Server lấy userId từ query/body nên Viewer #5 đọc được ví và lịch sử giao dịch của #8 (SEC-28), hồ sơ gồm email/SĐT của #6 (SEC-29), mã thẻ/voucher của người khác qua ?role=ADMIN hoặc ?userId= (SEC-30; mã thẻ = tiền thật), đổi quà bằng xu của người khác chỉ bằng cách sửa user_id trong request (SEC-31). Nhà QC #2 đọc được 3 chiến dịch của Nhà QC #3 với HTTP 200 (TC-040 yêu cầu 403). | E4: TC-040 | F4: tests/05-ads-admin.test.mjs: TC-040 tests/06-security.test.mjs: SEC-28…SEC-31 | G4: wallet/route.js L9; auth/me/route.js L9; redemptions/route.js L9–23; redeem/route.js L9; ads/route.js L10, L31–41; affiliate/route.js L9 | H4: Dùng user_id trong JWT làm chủ sở hữu; bỏ tham số userId/role/user_id khỏi query và body. Thêm điều kiện WHERE user_id = <từ token> (hoặc advertiser_id) cho mọi truy vấn dữ liệu cá nhân; chỉ Admin mới được truy vấn theo user bất kỳ. | I4: Mới
A5: BUG-04 | B5: Nghiêm trọng | C5: Mật khẩu “123456” đăng nhập được mọi tài khoản (kể cả ADMIN); đăng ký bỏ qua mật khẩu đã nhập | D5: login: password === "123456" luôn hợp lệ cho mọi tài khoản (SEC-02). Mật khẩu được so sánh trực tiếp với chuỗi lưu trong CSDL, nhập đúng chuỗi băm là vào được (SEC-03). register không lưu mật khẩu người dùng nhập mà gán cứng băm của “123456” (SEC-01) nên mật khẩu tự đặt không đăng nhập lại được. Thông báo lỗi tiết lộ “Mật khẩu mặc định demo là: 123456” (SEC-05). | E5: — | F5: tests/01-auth.test.mjs: SEC-01…SEC-03, SEC-05 | G5: auth/login/route.js L36–47; auth/register/route.js L46–47 | H5: Đăng ký: bcrypt.hash(password, 12). Đăng nhập: bcrypt.compare. Xóa mật khẩu mặc định và đoạn lộ mật khẩu trong thông báo; dùng một thông báo chung “Sai tài khoản hoặc mật khẩu” để không dò được tài khoản tồn tại. Seed tài khoản demo bằng băm thật. | I5: Mới
A6: BUG-05 | B6: Nghiêm trọng | C6: Server không tự đo thời gian xem, tin watched_seconds do client gửi | D6: Gọi complete ngay sau start (mới trôi qua 2/30 giây) nhưng khai watched_seconds = 30 vẫn được cộng 10 xu (TC-013); gọi sau 5 giây khai 30s vẫn được cộng (TC-016). Giao diện cũng luôn gửi watched_seconds = duration_sec (page.js L335) nên không có lớp nào chặn việc tua hoặc bỏ qua video. | E6: TC-013, TC-014, TC-016 | F6: tests/03-views.test.mjs: TC-013, TC-016 | G6: views/complete/route.js L51–63; app/page.js L328–336 | H6: Bỏ watched_seconds từ client. Tại complete tính elapsed = NOW() − started_at ở server (kèm heartbeat, xem BUG-12) và chỉ chấp nhận khi elapsed ≥ duration_sec − dung sai 1–2 giây; ngược lại đặt INVALID và trả 409 NOT_WATCHED_ENOUGH. | I6: Mới
A7: BUG-06 | B7: Nghiêm trọng | C7: complete không ràng buộc token với người xem, quảng cáo và trạng thái lượt xem | D7: User #9 nhận 10 xu bằng token của user #5 vì lượt xem chỉ được tìm theo view_token (SEC-10). Khai ad_id khác với quảng cáo đã start để nhận thưởng cao hơn: nhận 20 xu thay vì tối đa 5 xu (SEC-11). Lượt đã bị đánh INVALID vẫn “hồi sinh” và nhận xu khi gọi complete lần nữa vì chỉ chặn trạng thái COMPLETED (SEC-12). | E7: — | F7: tests/03-views.test.mjs: SEC-10…SEC-12 | G7: views/complete/route.js L8, L17–22, L31, L37–41, L85–88 | H7: Chỉ nhận view_token từ client. Truy vấn WHERE view_token = ? AND user_id = <từ JWT> AND view_status = "STARTED" FOR UPDATE; lấy ad_id và reward_xu từ chính bản ghi ad_views/ads của lượt đó; cộng xu cho chủ lượt xem. | I7: Mới
A8: BUG-07 | B8: Cao | C8: Tài khoản bị khóa vẫn đăng nhập thành công | D8: Đăng nhập tài khoản LOCKED trả HTTP 200, success = true kèm toàn bộ dữ liệu người dùng, chỉ đổi câu thông báo (TC-007; API-01 yêu cầu 403). Tài khoản Admin vừa khóa xong vẫn đăng nhập được (TC-044). | E8: TC-007, TC-044 | F8: tests/01-auth.test.mjs: CT-02, TC-007 tests/05-ads-admin.test.mjs: TC-044 | G8: auth/login/route.js L49–62 | H8: Nếu account_status = "LOCKED" trả 403 {success:false, message:"Tài khoản đã bị khóa"} và không trả user hay token; giao diện hiển thị thông báo từ response. | I8: Mới
A9: BUG-08 | B9: Cao | C9: complete không kiểm tra lại hạn mức ngày, trạng thái tài khoản và hạn dùng của token | D9: start chỉ đếm lượt đã COMPLETED nên bắt đầu nhiều lượt rồi hoàn tất cùng lúc vẫn vượt trần: 52 lượt hoàn tất trong một ngày (trần 50) (EXT-11). Tài khoản bị khóa giữa chừng vẫn nhận được xu (EXT-15). view_token tồn tại vô thời hạn: token tạo 2 giờ trước vẫn hoàn tất được (EXT-16). | E9: TC-019, TC-020 | F9: tests/03-views.test.mjs: EXT-11, EXT-15, EXT-16 | G9: views/start/route.js L26–41; views/complete/route.js L14–35 | H9: Trong cùng transaction của complete: kiểm tra account_status = "ACTIVE"; đếm lại lượt/xu trong ngày (khóa dòng user bằng SELECT … FOR UPDATE để tuần tự hóa); từ chối token quá hạn (ví dụ started_at + duration + 60 giây) và chuyển INVALID. | I9: Mới
A10: BUG-09 | B10: Cao | C10: Ngân sách quảng cáo không được giữ chỗ khi bắt đầu xem | D10: start chỉ kiểm tra spent_xu ≥ budget_xu, còn spent_xu chỉ tăng khi complete. QC còn 5 xu, xu thưởng 10 xu vẫn cho bắt đầu xem (TC-023). QC còn đúng 1 lượt: hai người cùng bắt đầu đều được, cả hai xem hết video rồi người thứ hai bị lỗi vì vi phạm ràng buộc spent_xu ≤ budget_xu (TC-024) – mất công xem mà không nhận xu. | E10: TC-022, TC-023, TC-024 | F10: tests/03-views.test.mjs: TC-023, TC-024 | G10: views/start/route.js L58–68; views/complete/route.js L78–82 | H10: Khi start, trong transaction SELECT … FOR UPDATE bảng ads; yêu cầu budget_xu − spent_xu − reserved_xu ≥ reward_xu rồi tăng giữ chỗ (cột reserved_xu hoặc bảng giữ chỗ). complete chuyển giữ chỗ thành đã chi; INVALID/token hết hạn thì nhả giữ chỗ. | I10: Mới
A11: BUG-10 | B11: Cao | C11: Đối tượng mục tiêu (ad_targeting) được lưu nhưng không dùng khi hiển thị và cho xem | D11: Nam 30 tuổi vẫn thấy và xem được quảng cáo nhắm nữ 18–24 tuổi ở Hà Nội (TC-009); ma trận giới tính × độ tuổi × tỉnh không được lọc (EXT-08). GET /api/ads và POST /views/start không hề đọc bảng ad_targeting. | E11: TC-009 | F11: tests/02-ads-list.test.mjs: EXT-08, TC-009 | G11: ads/route.js L43–64; views/start/route.js L57–66 | H11: LEFT JOIN ad_targeting và lọc: gender IS NULL OR gender = ?; tuổi (năm hiện tại − birth_year) nằm trong [age_from, age_to] khi có; province khớp. Lấy hồ sơ người xem từ CSDL theo JWT. Áp dụng cùng điều kiện ở /views/start. | I11: Mới
A12: BUG-11 | B12: Cao | C12: Giao diện đếm ngược bằng setInterval, không tạm dừng khi chuyển tab | D12: page.js không xử lý visibilitychange/document.hidden nên thời gian ngoài tab vẫn bị tính (TC-014). Kết hợp BUG-05 (server không đo giờ) nên không có lớp nào chặn. Kết luận dựa trên đọc mã nguồn, chưa thử bằng trình duyệt thật. | E12: TC-014 | F12: tests/03-views.test.mjs: TC-014 | G12: app/page.js L306 (setInterval), L328–336 | H12: Lắng nghe visibilitychange: khi tab ẩn thì tạm dừng đếm và ngừng gửi heartbeat; server chỉ tính thời gian có heartbeat (BUG-12). Hiện thông báo “Hãy quay lại tab để tiếp tục xem”. | I12: Mới
... A35: BUG-34 | B35: Thấp | C35: Trang giới thiệu: hoa hồng từng người bạn được ghép theo họ tên trong ghi chú | D35: Hai bạn trùng họ tên thì hiển thị hoa hồng của nhau: bạn #13 chưa xem gì vẫn hiện 2 xu (AFF-06) vì truy vấn dùng LIKE "%[tên]%" trên ghi chú. | E35: — | F35: tests/08-affiliate.test.mjs: AFF-06 | G35: affiliate/route.js L55–59 | H35: Lưu referee_id vào xu_transactions (hoặc liên kết qua view_id/redemption_id → user) rồi SUM theo user_id thay vì LIKE theo tên. | I35: Mới

Sheet Chi tiết lần chạy
A1: STT | B1: Mã kiểm thử | C1: Test case (TC-01) | D1: File test | E1: Kết quả | F1: Thời gian (ms) | G1: Nội dung kiểm tra | H1: Kết quả thực tế (khi không đạt) | I1: Mã lỗi
A2: 1 | B2: SMOKE-01 | C2: — | D2: 00-smoke.test.mjs | E2: Đạt | F2: 40 | G2: nạp được dữ liệu mẫu và gọi được route handler thật
A3: 2 | B3: SMOKE-02 | C3: — | D3: 00-smoke.test.mjs | E3: Đạt | F3: 7 | G3: gọi được route động có tham số [id]
A4: 3 | B4: SMOKE-03 | C4: — | D4: 00-smoke.test.mjs | E4: Đạt | F4: 13 | G4: luồng xem quảng cáo đầy đủ chạy được (start -> complete)
A5: 4 | B5: SMOKE-04 | C5: — | D5: 00-smoke.test.mjs | E5: Đạt | F5: 6 | G5: không có transaction nào bị bỏ treo
A6: 5 | B6: TC-001 | C6: TC-001 | D6: 01-auth.test.mjs | E6: Đạt | F6: 35 | G6: đăng ký thành công: tạo tài khoản VIEWER, số dư 0 xu
A7: 6 | B7: TC-002 | C7: TC-002 | D7: 01-auth.test.mjs | E7: Đạt | F7: 4 | G7: đăng ký trùng email: bị từ chối, báo thông tin đã được dùng, không tạo thêm tài khoản
A8: 7 | B8: TC-003 | C8: TC-003 | D8: 01-auth.test.mjs | E8: Đạt | F8: 6 | G8: đăng ký trùng số điện thoại: bị từ chối, không tạo tài khoản
A9: 8 | B9: TC-004 | C9: TC-004 | D9: 01-auth.test.mjs | E9: Đạt | F9: 4 | G9: dưới 16 tuổi (năm sinh 2015): bị từ chối, không tạo tài khoản
A10: 9 | B10: TC-005 | C10: TC-005 | D10: 01-auth.test.mjs | E10: Không đạt | F10: 2 | G10: OTP sai 3 lần buộc gửi OTP mới (cần endpoint xác thực OTP) | H10: Chưa có endpoint /auth/verify-otp: chức năng OTP khi đăng ký chưa được cài đặt (register tạo tài khoản ngay, không qua OTP) | I10: BUG-21
A11: 10 | B11: TC-006 | C11: TC-006 | D11: 01-auth.test.mjs | E11: Không đạt | F11: 2 | G11: OTP hết hạn sau 5 phút (cần endpoint xác thực OTP) | H11: Chưa có endpoint /auth/verify-otp nên không có OTP để hết hạn | I11: BUG-21
A12: 11 | B12: TC-007 | C12: TC-007 | D12: 01-auth.test.mjs | E12: Không đạt | F12: 9 | G12: đăng nhập tài khoản bị khóa: bị từ chối, báo tài khoản bị khóa, không trả dữ liệu người dùng | H12: API trả success=true (HTTP 200) cho tài khoản LOCKED và còn trả cả dữ liệu người dùng; chỉ có thông báo nhắc khóa true !== false | I12: BUG-07
A13: 12 | B13: SEC-01 | C13: — | D13: 01-auth.test.mjs | E13: Không đạt | F13: 7 | G13: mật khẩu nhập lúc đăng ký phải là mật khẩu đăng nhập của tài khoản đó | H13: Đăng nhập bằng đúng mật khẩu vừa đăng ký bị từ chối (HTTP 401): register bỏ qua mật khẩu người dùng và luôn gán mật khẩu demo 401 !== 200 | I13: BUG-04
A14: 13 | B14: SEC-02 | C14: — | D14: 01-auth.test.mjs | E14: Không đạt | F14: 3 | G14: không đăng nhập được bằng mật khẩu demo "123456" vào tài khoản có mật khẩu khác | H14: Đăng nhập thành công (HTTP 200) bằng "123456" vào tài khoản KHÔNG dùng mật khẩu này (cả ADMIN cũng vậy) 200 !== 401 | I14: BUG-04
A15: 14 | B15: SEC-03 | C15: — | D15: 01-auth.test.mjs | E15: Không đạt | F15: 4 | G15: không đăng nhập được bằng chính chuỗi băm của mật khẩu | H15: Mật khẩu đang được so sánh trực tiếp với chuỗi lưu trong CSDL (không dùng bcrypt.compare) 200 !== 401 | I15: BUG-04
A16: 15 | B16: SEC-04 | C16: — | D16: 01-auth.test.mjs | E16: Đạt | F16: 3 | G16: sai mật khẩu bị từ chối (401)
A17: 16 | B17: SEC-05 | C17: — | D17: 01-auth.test.mjs | E17: Không đạt | F17: 6 | G17: thông báo lỗi đăng nhập không lộ mật khẩu và không cho dò tài khoản tồn tại | H17: Thông báo lỗi tiết lộ mật khẩu: "Mật khẩu không chính xác! (Mật khẩu mặc định demo là: 123456)" | I17: BUG-04
A18: 17 | B18: SEC-06 | C18: — | D18: 01-auth.test.mjs | E18: Không đạt | F18: 3 | G18: đăng nhập thành công trả JWT để xác thực các API sau (API-01) | H18: Đăng nhập không phát hành token/JWT; AUTH_SECRET trong .env.local không được dùng ở đâu | I18: BUG-01
A19: 18 | B19: SEC-07 | C19: — | D19: 01-auth.test.mjs | E19: Đạt | F19: 8 | G19: chống SQL injection ở form đăng nhập
A20: 19 | B20: SEC-08 | C20: — | D20: 01-auth.test.mjs | E20: Đạt | F20: 3 | G20: phản hồi đăng nhập không chứa password_hash
A21: 20 | B21: EXT-01 | C21: — | D21: 01-auth.test.mjs | E21: Đạt | F21: 16 | G21: thiếu trường bắt buộc (email/SĐT/họ tên/mật khẩu) bị từ chối 400
A22: 21 | B22: EXT-02 | C22: — | D22: 01-auth.test.mjs | E22: Đạt | F22: 4 | G22: biên tuổi: 15 tuổi bị từ chối, 16 tuổi được chấp nhận
A23: 22 | B23: EXT-03 | C23: — | D23: 01-auth.test.mjs | E23: Không đạt | F23: 9 | G23: không thể qua mặt kiểm tra tuổi bằng cách bỏ trống/gửi sai năm sinh | H23: Đăng ký thành công khi năm sinh = không gửi | "" | 0 | "abc" | null (bỏ qua giới hạn 16 tuổi) | I23: BUG-28
A24: 23 | B24: EXT-04 | C24: — | D24: 01-auth.test.mjs | E24: Không đạt | F24: 9 | G24: email và số điện thoại sai định dạng bị từ chối | H24: API-01 yêu cầu kiểm tra dữ liệu đầu vào, nhưng các giá trị sau được chấp nhận: khong-phai-email / 0912345670 ; a@b / 0912345671 ; ok@test.vn / abcdefghij ; ok2@test.vn / 12 | I24: BUG-28
A25: 24 | B25: EXT-05 | C25: — | D25: 01-auth.test.mjs | E25: Không đạt | F25: 7 | G25: email có khoảng trắng thừa được cắt trước khi lưu (để đăng nhập lại được) | H25: Không đăng nhập lại được bằng email đã nhập (HTTP 401): register lưu nguyên khoảng trắng còn login thì cắt 401 !== 200 | I25: BUG-28
A26: 25 | B26: EXT-06 | C26: — | D26: 01-auth.test.mjs | E26: Đạt | F26: 5 | G26: mã giới thiệu: hợp lệ thì liên kết; mã sai hoặc người giới thiệu bị khóa thì bỏ qua
A27: 26 | B27: EXT-07 | C27: — | D27: 01-auth.test.mjs | E27: Đạt | F27: 2 | G27: dữ liệu có ký tự SQL được lưu nguyên văn, không phá CSDL
A28: 27 | B28: CT-01 | C28: — | D28: 01-auth.test.mjs | E28: Không đạt | F28: 8 | G28: email/SĐT trùng trả 409 (API-01) | H28: trùng email trả 400 400 !== 409 | I28: BUG-33
A29: 28 | B29: CT-02 | C29: — | D29: 01-auth.test.mjs | E29: Không đạt | F29: 3 | G29: đăng nhập tài khoản bị khóa trả 403 (API-01) | H29: trả 200 200 !== 403 | I29: BUG-07
A30: 29 | B30: CT-06 | C30: — | D30: 01-auth.test.mjs | E30: Không đạt | F30: 21 | G30: body JSON sai định dạng trả 400, không phải 500 kèm lỗi nội bộ | H30: Các route sau không kiểm soát JSON lỗi: POST /api/auth/login -> 500 "Expected property name or '}' in JSON at position 1 (line 1 column 2)" POST /api/auth/register -> 500 "Expected property name or '}' in JSON at position 1 (line 1 column 2)" POST /api/views/start -> 500 "Expected property name or '}' in JSON at position 1 (line 1 column 2)" POST /api/views/complete -> 500 "Expected property name or '}' in JSON at position 1 (line 1 column 2)" POST /api/redeem -> 500 "Expected property name or '}' in JSON at position 1 (line 1 column 2)" POST /api/ads -> 500 "Expected property name or '}' in JSON at position 1 (line 1 column 2)" | I30: BUG-30
A31: 30 | B31: SEC-09 | C31: — | D31: 01-auth.test.mjs | E31: Không đạt | F31: 6 | G31: lỗi CSDL không được trả nguyên văn cho client (API-01: không tiết lộ thông tin nhạy cảm) | H31: Phản hồi lộ chi tiết nội bộ: {"success":false,"message":"ER_NO_SUCH_TABLE: Table 'youtube_xu.users' doesn't exist"} | I31: BUG-30
A32: 31 | B32: TC-008 | C32: TC-008 | D32: 02-ads-list.test.mjs | E32: Đạt | F32: 36 | G32: chỉ hiện quảng cáo ACTIVE, còn ngân sách và đang trong thời gian chạy
A33: 32 | B33: TC-009 | C33: TC-009 | D33: 02-ads-list.test.mjs | E33: Không đạt | F33: 5 | G33: lọc theo đối tượng mục tiêu: QC cho nữ 18–24 Hà Nội không hiện với nam 30 tuổi | H33: Nam 30 tuổi vẫn thấy quảng cáo nhắm nữ 18–24: API GET /api/ads không hề dùng bảng ad_targeting | I33: BUG-10
A34: 33 | B34: TC-009 | C34: TC-009 | D34: 02-ads-list.test.mjs | E34: Đạt | F34: 5 | G34: người đúng đối tượng (nữ 20 tuổi Hà Nội) vẫn thấy quảng cáo đó
A35: 34 | B35: EXT-08 | C35: — | D35: 02-ads-list.test.mjs | E35: Không đạt | F35: 16 | G35: ma trận đối tượng mục tiêu (giới tính × tuổi × tỉnh, kể cả giá trị biên) | H35: Sai đối tượng mục tiêu: nữ 17 tuổi HN (dưới biên): thấy (đúng ra phải không thấy) nữ 25 tuổi HN (trên biên): thấy (đúng ra phải không thấy) nam 20 tuổi HN (sai giới tính): thấy (đúng ra phải không thấy) nữ 20 tuổi TP.HCM (sai tỉnh): thấy (đúng ra phải không thấy) | I35: BUG-10
A36: 35 | B36: EXT-09 | C36: — | D36: 02-ads-list.test.mjs | E36: Đạt | F36: 4 | G36: quảng cáo nhắm nhiều khu vực (HOẶC): thấy khi thuộc một trong các khu vực
A37: 36 | B37: TC-010 | C37: TC-010 | D37: 02-ads-list.test.mjs | E37: Đạt | F37: 3 | G37: lọc theo danh mục: chỉ hiện quảng cáo của danh mục được chọn
A38: 37 | B38: TC-011 | C38: TC-011 | D38: 02-ads-list.test.mjs | E38: Đạt | F38: 5 | G38: quảng cáo đã xem hôm nay được đánh dấu để khóa nút xem
A39: 38 | B39: TC-011 | C39: TC-011 | D39: 02-ads-list.test.mjs | E39: Đạt | F39: 3 | G39: lượt xem chưa hoàn tất (STARTED/INVALID) không làm quảng cáo bị khóa
A40: 39 | B40: TC-012 | C40: TC-012 | D40: 03-views.test.mjs | E40: Đạt | F40: 40 | G40: xem đủ thời lượng: cộng xu, sinh dòng EARN, tăng spent_xu
...
